<?xml version="1.0" ?>
<sdf version="1.4">  
<model name="Manipulador">
  <static>false</static>

<!--===================== LINKS =====================-->
  <!-- Support - 1 parte -->
  <link name="Support">
    <pose>0 0 0.54 0 0 0</pose>
    <inertial>
      <!-- Volume:  4.9678384375e-01 -->
      <mass> 1.0 </mass>

      <!-- Center of mass:  7.1726190000e-02  8.3274000000e-04  1.3966684000e-01 -->
      <pose>  7.1726190000e-02  8.3274000000e-04  1.3966684000e-01 0 0 0 </pose>

      <!-- Inertia matrix -->
      <inertia>
        <ixx>  4.2189241908e-01 </ixx>
        <ixy>  5.9379537743e-04 </ixy>
        <ixz>  6.7296383368e-03 </ixz>
        <iyy>  3.8385869267e-01 </iyy>
        <iyz>  2.9011387812e-04 </iyz>
        <izz>  5.6774468564e-01 </izz>
      </inertia>
    </inertial>

    <collision name="SupCollision">
      <geometry>
        <mesh>
          <uri>model://zortrax/meshes/Support/Support.stl</uri>
        </mesh>
      </geometry>
    </collision>

    <visual name="SupVsual">
      <geometry>
        <mesh>
          <uri>model://zortrax/meshes/Support/Support.stl</uri>
        </mesh>
      </geometry>
    </visual>

    <collision name="RingCollision">
      <pose>0.00014 -0.002 0.59 0 0 -0.004</pose>
      <geometry>
        <mesh>
          <uri>model://zortrax/meshes/Support/Ring.stl</uri>
        </mesh>
      </geometry>
    </collision>

    <visual name="RingVisual">
      <pose>0.00014 -0.002 0.59 0 0 -0.004</pose>
      <geometry>
        <mesh>
          <uri>model://zortrax/meshes/Support/Ring.stl</uri>
        </mesh>
      </geometry>
    </visual>
  </link>

  <!-- Base - 2 parte -->
  <link name="Base">
    <pose>0 0 1.13 0 0 0</pose>
    <inertial>
      <!-- Volume:  5.1779593750e-01 -->
      <mass> 1.0 </mass>

      <!-- Center of mass:  1.0734090000e-02 -3.1306260000e-02 -2.0209423000e-01 -->
      <pose>  1.0734090000e-02 -3.1306260000e-02 -2.0209423000e-01 0 0 0 </pose>

      <!-- Inertia matrix -->
      <inertia>
        <ixx>  2.4985402980e-01 </ixx>
        <ixy>  2.8065590994e-03 </ixy>
        <ixz> -1.9526662277e-02 </ixz>
        <iyy>  2.0700495202e-01 </iyy>
        <iyz>  2.6764250154e-04 </iyz>
        <izz>  1.9692468754e-01 </izz>
      </inertia>
    </inertial>

    <collision name="TRingCollision">
      <geometry>
        <mesh>
          <uri>model://zortrax/meshes/Base/ToothedRing.stl</uri>
        </mesh>
      </geometry>
    </collision>
    <visual name="TRingVisual">
      <geometry>
        <mesh>
          <uri>model://zortrax/meshes/Base/ToothedRing.stl</uri>
        </mesh>
      </geometry>
    </visual>

    <collision name="baseCollision">
      <pose>0 0  0.63 0 0 0</pose>
      <geometry>
        <mesh>
          <uri>model://zortrax/meshes/Base/Base.stl</uri>
        </mesh>
      </geometry>
    </collision>
    <visual name="baseVisual">
      <pose>0 0  0.63 0 0 0</pose>
      <geometry>
        <mesh>
          <uri>model://zortrax/meshes/Base/Base.stl</uri>
        </mesh>
      </geometry>
    </visual>

    <collision name="coverLCollision">
      <pose>0.117 -0.565 0.885 0 0 0</pose>
      <geometry>
        <mesh>
          <uri>model://zortrax/meshes/Base/coverBaseL.stl</uri>
        </mesh>
      </geometry>
    </collision>
    <visual name="coverLVisual">
      <pose>0.117 -0.565 0.885 0 0 0</pose>
      <geometry>
        <mesh>
          <uri>model://zortrax/meshes/Base/coverBaseL.stl</uri>
        </mesh>
      </geometry>
    </visual>

    <collision name="coverRCollision">
      <pose>0.117 0.535 0.885 0 0 0</pose>
      <geometry>
        <mesh>
          <uri>model://zortrax/meshes/Base/coverBaseR.stl</uri>
        </mesh>
      </geometry>
    </collision>
    <visual name="coverRVisual">
      <pose>0.117 0.535 0.885 0 0 0</pose>
      <geometry>
        <mesh>
          <uri>model://zortrax/meshes/Base/coverBaseR.stl</uri>
        </mesh>
      </geometry>
    </visual>
  </link>

  <!-- Lower Arm - 3 parte -->
  <link name="LowerArm">
    <pose>0.117 -0.015 2.15 0 0 0</pose>
    <inertial>
      <!-- Volume:  7.2606862500e-01 -->
      <mass> 0.2 </mass>

      <!-- Center of mass: -2.9281710000e-02 -1.9001520000e-02  4.2914791000e-01 -->
      <pose> -2.9281710000e-02 -1.9001520000e-02  4.2914791000e-01 0 0 0 </pose>

      <!-- Inertia matrix -->
      <inertia>
        <ixx>  2.0930545622e-01 </ixx>
        <ixy> -2.3801660277e-04 </ixy>
        <ixz>  2.1646688011e-03 </ixz>
        <iyy>  1.9833343770e-01 </iyy>
        <iyz>  1.4079684100e-04 </iyz>
        <izz>  5.1472661830e-02 </izz>
      </inertia>
    </inertial>

    <collision name="Arm1Collision">
      <geometry>
        <mesh>
          <uri>model://zortrax/meshes/LowerArm/Arm1Lower.stl</uri>
        </mesh>
      </geometry>
    </collision>
    <visual name="Arm1Visual">
      <geometry>
        <mesh>
          <uri>model://zortrax/meshes/LowerArm/Arm1Lower.stl</uri>
        </mesh>
      </geometry>
    </visual>

    <collision name="pinoCollision">
      <pose>0.005 0 -0.135 1.5708 1.5708 0</pose>
      <geometry>
        <cylinder>
          <radius>0.04</radius>
          <length>0.8</length>
        </cylinder>
      </geometry>
    </collision>
    <visual name="pinoVisual">
      <pose>0.005 0 -0.135 1.5708 1.5708 0</pose>
      <geometry>
        <cylinder>
          <radius>0.04</radius>
          <length>0.8</length>
        </cylinder>
      </geometry>
    </visual>

    <collision name="Arm1UpperCollision">
      <pose>-0.002 0.0216 1.15 0 0 0</pose>
      <geometry>
        <mesh>
          <uri>model://zortrax/meshes/LowerArm/Arm1Upper.stl</uri>
        </mesh>
      </geometry>
    </collision>
    <visual name="Arm1UpperVisual">
      <pose>-0.002 0.0216 1.15 0 0 0</pose>
      <geometry>
        <mesh>
          <uri>model://zortrax/meshes/LowerArm/Arm1Upper.stl</uri>
        </mesh>
      </geometry>
    </visual>

    <visual name="BaseGearVisual">
      <pose>0.02 0.22 -0.3 1.5708 3.1 0</pose>
      <geometry>
        <mesh>
          <uri>model://zortrax/meshes/LowerArm/BaseGear.stl</uri>
        </mesh>
      </geometry>
    </visual>
  </link>

  <!-- Upper Arm - 4 parte -->
  <link name="UpperArm">
    <pose>0.22 0.001 3.63 0 0 0</pose>
    <inertial>
      <!-- Volume:  6.3770118750e-01 -->
      <mass> 0.2 </mass>

      <!-- Center of mass:  5.4617455000e-01  4.7914700000e-03  7.7464810000e-02 -->
      <pose>  5.4617455000e-01  4.7914700000e-03  7.7464810000e-02 0 0 0 </pose>

      <!-- Inertia matrix -->
      <inertia>
        <ixx>  3.0737638857e-02 </ixx>
        <ixy> -5.9791790806e-03 </ixy>
        <ixz> -1.8271795362e-02 </ixz>
        <iyy>  2.0499584345e-01 </iyy>
        <iyz> -8.6160095162e-04 </iyz>
        <izz>  2.0368961160e-01 </izz>
      </inertia>
    </inertial>
      
    <collision name="Arm2Visual">
      <geometry>
        <mesh>
          <uri>model://zortrax/meshes/UpperArm/Arm2.stl</uri>
        </mesh>
      </geometry>
    </collision>
    <visual name="Arm2Visual">
      <geometry>
        <mesh>
          <uri>model://zortrax/meshes/UpperArm/Arm2.stl</uri>
        </mesh>
      </geometry>
    </visual>

    <collision name="pino2Visual">
      <pose>-0.103 0 -0.035 1.5708 1.5708 0</pose>
      <geometry>
        <cylinder>
          <radius>0.04</radius>
          <length>0.7</length>
        </cylinder>
      </geometry>
    </collision>
    <visual name="pino2Visual">
      <pose>-0.103 0 -0.035 1.5708 1.5708 0</pose>
      <geometry>
        <cylinder>
          <radius>0.04</radius>
          <length>0.7</length>
        </cylinder>
      </geometry>
    </visual>

    <collision name="Arm3Visual">
      <pose>1.1855 0.015 0.125 0 0 0</pose>
      <geometry>
        <mesh>
          <uri>model://zortrax/meshes/UpperArm/Arm3.stl</uri>
        </mesh>
      </geometry>
    </collision>
    <visual name="Arm3Visual">
      <pose>1.1855 0.015 0.125 0 0 0</pose>
      <geometry>
        <mesh>
          <uri>model://zortrax/meshes/UpperArm/Arm3.stl</uri>
        </mesh>
      </geometry>
    </visual>
  </link>

  <!-- GrasperHolder - 5 parte -->
  <link name="GrasperHolder">
    <pose>1.943 0 3.675 0 0 0</pose>
    <inertial>
      <!-- Volume:  4.6362562500e-02 -->
      <mass> 0.1 </mass>

      <!-- Center of mass: -3.0875000000e-04  8.1761400000e-03  2.6252960000e-02 -->
      <pose> -3.0875000000e-04  8.1761400000e-03  2.6252960000e-02 0 0 0 </pose>

      <!-- Inertia matrix -->
      <inertia>
        <ixx>  5.9870685534e-03 </ixx>
        <ixy>  9.5459665061e-06 </ixy>
        <ixz> -1.1134579051e-05 </ixz>
        <iyy>  5.9527261894e-03 </iyy>
        <iyz> -2.7627261220e-04 </iyz>
        <izz>  3.5809690200e-03 </izz>
      </inertia>
    </inertial>

    <collision name="GrasperHolderVisual">
      <geometry>
        <mesh>
          <uri>model://zortrax/meshes/GrasperHolder/GrasperHolder.stl</uri>
        </mesh>
      </geometry>
    </collision>
    <visual name="GrasperHolderVisual">
      <geometry>
        <mesh>
          <uri>model://zortrax/meshes/GrasperHolder/GrasperHolder.stl</uri>
        </mesh>
      </geometry>
    </visual>
  </link>

  <!-- Grasper - 6 parte -->
  <link name="Grasper">
    <pose>1.943 -0.0088 3.2 0 0 0</pose>
    <inertial>
      <!-- Volume:  5.9164203125e-02 -->
      <mass> 0.1 </mass>

      <!-- Center of mass:  3.3870000000e-04  4.5093000000e-04 -2.3830086000e-01 -->
      <pose>  3.3870000000e-04  4.5093000000e-04 -2.3830086000e-01 0 0 0 </pose>

      <!-- Inertia matrix -->
      <inertia>
        <ixx>  1.0964352864e-02 </ixx>
        <ixy>  2.3511915923e-06 </ixy>
        <ixz>  1.0524369545e-05 </ixz>
        <iyy>  1.2156277648e-02 </iyy>
        <iyz>  1.0870709670e-05 </iyz>
        <izz>  1.9657217347e-03 </izz>
      </inertia>
    </inertial>

    <collision name="GrasperBodyVisual">
      <geometry>
        <mesh>
          <uri>model://zortrax/meshes/Grasper/GrasperBody.stl</uri>
        </mesh>
      </geometry>
    </collision>
    <visual name="GrasperBodyVisual">
      <geometry>
        <mesh>
          <uri>model://zortrax/meshes/Grasper/GrasperBody.stl</uri>
        </mesh>
      </geometry>
    </visual>

    <collision name="Grasper1Visual">
      <pose>-0.1163 0 -0.485 1.5708 -1.5708 0</pose>
      <geometry>
        <mesh>
          <uri>model://zortrax/meshes/Grasper/Grasper1.stl</uri>
        </mesh>
      </geometry>
    </collision>
    <visual name="Grasper1Visual">
      <pose>-0.1163 0 -0.485 1.5708 -1.5708 0</pose>
      <geometry>
        <mesh>
          <uri>model://zortrax/meshes/Grasper/Grasper1.stl</uri>
        </mesh>
      </geometry>
    </visual>

    <collision name="Grasper2Visual">
      <pose>0.1163 0 -0.485 -1.5708 -1.5708 0</pose>
      <geometry>
        <mesh>
          <uri>model://zortrax/meshes/Grasper/Grasper2.stl</uri>
        </mesh>
      </geometry>
    </collision>
    <visual name="Grasper2Visual">
      <pose>0.1163 0 -0.485 -1.5708 -1.5708 0</pose>
      <geometry>
        <mesh>
          <uri>model://zortrax/meshes/Grasper/Grasper2.stl</uri>
        </mesh>
      </geometry>
    </visual>
  </link>

<!--===================== Joints ===================== -->
  <!-- joint 1 - Support/Base -->
  <joint type="revolute" name="first">
    <pose>0 0 1.14 0 0 0</pose>
    <parent>Support</parent>
    <child>Base</child>

    <!-- The axis defines the joint's degree of freedom -->
    <axis>
      <!-- Revolve around the z-axis -->
      <xyz>0 0 1</xyz>
      <!-- Limit refers to the range of motion of the joint -->
      <!-- Use a very large number to indicate a continuous revolution -->
      <limit>
        <lower>-3.14159</lower>
        <upper>3.14159</upper>
      </limit>
      <dynamics>
        <damping>5</damping>
      </dynamics>
    </axis>
  </joint>

  <!-- joint 2 - Base/ Lower Arm -->
  <joint type="revolute" name="second">
    <pose>0 0 -0.14 0 0 0</pose>
    <parent>Base</parent>
    <child>LowerArm</child>
    <axis>
      <!-- Revolve around the Y-axis -->
      <xyz>0 1 0</xyz>
      <limit>
        <!-- 1.5708 rad = 90 graus -->
        <lower>-1.5708</lower>
        <upper>1.5708</upper>
      </limit>
      <dynamics>
        <damping>10</damping>
      </dynamics>
    </axis>
  </joint>

  <!-- joint 3 - Lower Arm/ Upper Arm  -->
  <joint type="revolute" name="third">
    <pose>-0.103 0 -0.035 0 0 0</pose>
    <parent>LowerArm</parent>
    <child>UpperArm</child>

    <axis>
      <!-- Revolve around the Y-axis -->
      <xyz>0 1 0</xyz>
      <limit>
        <!-- 0.7854 rad = 45 graus -->
        <lower>-1.5708</lower>
        <upper>0</upper>
      </limit>
      <dynamics>
        <damping>5</damping>
      </dynamics>
    </axis>
  </joint>

  <!-- joint 4 - Upper Arm/Grasper Holder  -->
  <joint type="revolute" name="fourth">
    <pose>0 0 0.09 0 0 0</pose>
    <parent>UpperArm</parent>
    <child>GrasperHolder</child>

    <axis>
      <!-- Revolve around the Y-axis -->
      <xyz>0 1 0</xyz>
      <limit>
        <lower>-1.5708</lower>
        <upper>0</upper>
      </limit>
      <dynamics>
        <damping>5</damping>
      </dynamics>
    </axis>
  </joint>

  <!-- joint 5 - Grasper Holder/Grasper  -->
  <joint type="revolute" name="fifth">
    <pose>0 0 0 0 0 0</pose>
    <parent>GrasperHolder</parent>
    <child>Grasper</child>

    <axis>
      <!-- Revolve around the Y-axis -->
      <xyz>0 0 1</xyz>
      <!-- 3.14159 rad = 180 graus -->
      <limit>
        <lower>-1.5708</lower>
        <upper>1.5708</upper>
      </limit>
      <dynamics>
        <damping>1</damping>
      </dynamics>
    </axis>
  </joint>

  <!-- support fixed on floor  -->
  <joint name="floor" type="fixed">
    <parent>Support</parent>
    <child>ground_plane::link</child>
    <pose>0.0 0.0 0.0 0.0 0.0 0.0</pose>
    <axis>
      <xyz>1.0 0.0 0.0</xyz>
    </axis>
  </joint>
    
  </model>
</sdf>